Workbook

Sheet Data Mentah
A1: Responden | B1: Q1 | C1: Q2 | D1: Q3 | E1: Q4 | F1: Q5 | G1: Q6 | H1: Q7 | I1: Q8 | J1: Q9 | K1: Q10 | L1: Q11 | M1: Q12 | N1: Q13 | O1: Q14 | P1: Q15 | Q1: Q16 | R1: Q17 | S1: Q18 | T1: Q19 | U1: Q20 | V1: Q21 | W1: Q22 | X1: Q23 | Y1: Q24 | Z1: Q25 | AA1: Q26 | AB1: Q27 | AC1: Q28 | AD1: Q29 | AE1: Q30 | AF1: Q31 | AG1: Q32 | AH1: Q33 | AI1: Q34 | AJ1: Q35
A2: Dinas Sosial | B2: 3 | C2: 3 | D2: 2 | E2: 2 | F2: 3 | G2: 2 | H2: 1 | I2: 3 | J2: 3 | K2: 2 | L2: 2 | M2: 2 | N2: 2 | O2: 2 | P2: 2 | Q2: 2 | R2: 3 | S2: 3 | T2: 3 | U2: 3 | V2: 3 | W2: 2 | X2: 3 | Y2: 3 | Z2: 3 | AA2: 3 | AB2: 3 | AC2: 2 | AD2: 2 | AE2: 2 | AF2: 3 | AG2: 2 | AH2: 3 | AI2: 3 | AJ2: 2
A3: Dinas Komunikasi dan Informatika | B3: 3 | C3: 3 | D3: 3 | E3: 3 | F3: 3 | G3: 3 | H3: 3 | I3: 3 | J3: 3 | K3: 3 | L3: 3 | M3: 3 | N3: 2 | O3: 3 | P3: 3 | Q3: 3 | R3: 3 | S3: 3 | T3: 3 | U3: 3 | V3: 3 | W3: 3 | X3: 3 | Y3: 3 | Z3: 3 | AA3: 3 | AB3: 4 | AC3: 3 | AD3: 3 | AE3: 3 | AF3: 3 | AG3: 3 | AH3: 3 | AI3: 3 | AJ3: 3
A4: Bagian Kesejahteraan Rakyat Sekretariat Daerah | B4: 3 | C4: 3 | D4: 3 | E4: 3 | F4: 3 | G4: 3 | H4: 3 | I4: 3 | J4: 3 | K4: 2 | L4: 2 | M4: 3 | N4: 2 | O4: 3 | P4: 3 | Q4: 3 | R4: 3 | S4: 3 | T4: 3 | U4: 3 | V4: 3 | W4: 2 | X4: 3 | Y4: 3 | Z4: 3 | AA4: 2 | AB4: 3 | AC4: 3 | AD4: 3 | AE4: 3 | AF4: 3 | AG4: 3 | AH4: 3 | AI4: 3 | AJ4: 3
A5: Dinas Kesehatan | B5: 3 | C5: 3 | D5: 2 | E5: 2 | F5: 2 | G5: 2 | H5: 2 | I5: 1 | J5: 3 | K5: 2 | L5: 3 | M5: 1 | N5: 2 | O5: 2 | P5: 3 | Q5: 3 | R5: 3 | S5: 2 | T5: 3 | U5: 3 | V5: 2 | W5: 3 | X5: 2 | Y5: 2 | Z5: 2 | AA5: 2 | AB5: 3 | AC5: 2 | AD5: 3 | AE5: 3 | AF5: 3 | AG5: 3 | AH5: 3 | AI5: 3 | AJ5: 1
A6: DISPERPUSIP | B6: 3 | C6: 3 | D6: 2 | E6: 2 | F6: 3 | G6: 3 | H6: 2 | I6: 2 | J6: 2 | K6: 2 | L6: 2 | M6: 2 | N6: 2 | O6: 2 | P6: 3 | Q6: 3 | R6: 4 | S6: 2 | T6: 4 | U6: 4 | V6: 4 | W6: 1 | X6: 2 | Y6: 2 | Z6: 2 | AA6: 2 | AB6: 2 | AC6: 2 | AD6: 2 | AE6: 2 | AF6: 2 | AG6: 2 | AH6: 2 | AI6: 3 | AJ6: 3
A7: Bagian Perekonomian dan Sumber Daya Alam | B7: 4 | C7: 3 | D7: 4 | E7: 3 | F7: 4 | G7: 3 | H7: 4 | I7: 4 | J7: 3 | K7: 2 | L7: 2 | M7: 3 | N7: 3 | O7: 3 | P7: 4 | Q7: 4 | R7: 4 | S7: 3 | T7: 4 | U7: 4 | V7: 3 | W7: 4 | X7: 3 | Y7: 3 | Z7: 3 | AA7: 3 | AB7: 3 | AC7: 3 | AD7: 3 | AE7: 3 | AF7: 4 | AG7: 3 | AH7: 3 | AI7: 4 | AJ7: 4
A8: Dinas Sosial | B8: 4 | C8: 4 | D8: 4 | E8: 4 | F8: 3 | G8: 3 | H8: 3 | I8: 3 | J8: 3 | K8: 3 | L8: 3 | M8: 3 | N8: 3 | O8: 3 | P8: 3 | Q8: 3 | R8: 3 | S8: 3 | T8: 3 | U8: 4 | V8: 4 | W8: 4 | X8: 4 | Y8: 4 | Z8: 4 | AA8: 3 | AB8: 4 | AC8: 3 | AD8: 3 | AE8: 3 | AF8: 4 | AG8: 4 | AH8: 4 | AI8: 4 | AJ8: 4
A9: Dinas Kesehatan | B9: 3 | C9: 3 | D9: 3 | E9: 3 | F9: 3 | G9: 3 | H9: 4 | I9: 3 | J9: 3 | K9: 3 | L9: 3 | M9: 4 | N9: 4 | O9: 4 | P9: 4 | Q9: 4 | R9: 4 | S9: 4 | T9: 4 | U9: 4 | V9: 4 | W9: 4 | X9: 4 | Y9: 3 | Z9: 4 | AA9: 3 | AB9: 4 | AC9: 3 | AD9: 4 | AE9: 3 | AF9: 4 | AG9: 3 | AH9: 4 | AI9: 4 | AJ9: 3
A10: BKPSDM Kota Batu | B10: 4 | C10: 3 | D10: 3 | E10: 3 | F10: 3 | G10: 3 | H10: 3 | I10: 3 | J10: 4 | K10: 3 | L10: 2 | M10: 3 | N10: 3 | O10: 3 | P10: 3 | Q10: 3 | R10: 3 | S10: 3 | T10: 3 | U10: 3 | V10: 3 | W10: 3 | X10: 3 | Y10: 3 | Z10: 4 | AA10: 3 | AB10: 3 | AC10: 3 | AD10: 3 | AE10: 3 | AF10: 3 | AG10: 4 | AH10: 3 | AI10: 3 | AJ10: 3
A11: Badan Penanggulangan Bencana Daerah Kota Batu | B11: 4 | C11: 4 | D11: 4 | E11: 4 | F11: 4 | G11: 4 | H11: 4 | I11: 4 | J11: 4 | K11: 4 | L11: 4 | M11: 4 | N11: 4 | O11: 4 | P11: 4 | Q11: 4 | R11: 4 | S11: 4 | T11: 4 | U11: 4 | V11: 4 | W11: 4 | X11: 4 | Y11: 4 | Z11: 4 | AA11: 4 | AB11: 4 | AC11: 4 | AD11: 4 | AE11: 4 | AF11: 4 | AG11: 4 | AH11: 4 | AI11: 4 | AJ11: 4
A12: Dinas Pertanian dan Ketahanan Pangan | B12: 3 | C12: 2 | D12: 2 | E12: 2 | F12: 3 | G12: 3 | H12: 2 | I12: 2 | J12: 2 | K12: 3 | L12: 2 | M12: 2 | N12: 2 | O12: 3 | P12: 3 | Q12: 3 | R12: 3 | S12: 3 | T12: 4 | U12: 3 | V12: 3 | W12: 2 | X12: 2 | Y12: 3 | Z12: 2 | AA12: 3 | AB12: 3 | AC12: 3 | AD12: 3 | AE12: 3 | AF12: 2 | AG12: 3 | AH12: 3 | AI12: 3 | AJ12: 3
A13: Dinas Tenaga Kerja | B13: 4 | C13: 4 | D13: 4 | E13: 4 | F13: 4 | G13: 4 | H13: 4 | I13: 3 | J13: 3 | K13: 3 | L13: 4 | M13: 4 | N13: 4 | O13: 3 | P13: 3 | Q13: 4 | R13: 3 | S13: 3 | T13: 3 | U13: 4 | V13: 4 | W13: 3 | X13: 3 | Y13: 3 | Z13: 3 | AA13: 3 | AB13: 4 | AC13: 3 | AD13: 4 | AE13: 4 | AF13: 4 | AG13: 3 | AH13: 3 | AI13: 3 | AJ13: 3
... A49: Dinas PUPR | B49: 3 | C49: 3 | D49: 2 | E49: 2 | F49: 2 | G49: 2 | H49: 2 | I49: 2 | J49: 2 | K49: 2 | L49: 1 | M49: 1 | N49: 1 | O49: 2 | P49: 3 | Q49: 3 | R49: 3 | S49: 2 | T49: 3 | U49: 3 | V49: 2 | W49: 3 | X49: 3 | Y49: 3 | Z49: 2 | AA49: 2 | AB49: 2 | AC49: 3 | AD49: 2 | AE49: 2 | AF49: 2 | AG49: 2 | AH49: 2 | AI49: 3 | AJ49: 3

Sheet Skor Variabel
A1: Responden | B1: X1_Komunikasi | C1: X2_SumberDaya | D1: X3_Disposisi | E1: X4_StrukturBirokrasi | F1: Y_Keberhasilan
A2: Dinas Sosial | B2: =AVERAGE('Data Mentah'!B2:H2) -> 2.2857143 | C2: =AVERAGE('Data Mentah'!I2:O2) -> 2.2857143 | D2: =AVERAGE('Data Mentah'!P2:V2) -> 2.7142857 | E2: =AVERAGE('Data Mentah'!W2:AB2) -> 2.8333333 | F2: =AVERAGE('Data Mentah'!AC2:AJ2) -> 2.375
A3: Dinas Komunikasi dan Informatika | B3: =AVERAGE('Data Mentah'!B3:H3) -> 3 | C3: =AVERAGE('Data Mentah'!I3:O3) -> 2.8571429 | D3: =AVERAGE('Data Mentah'!P3:V3) -> 3 | E3: =AVERAGE('Data Mentah'!W3:AB3) -> 3.1666667 | F3: =AVERAGE('Data Mentah'!AC3:AJ3) -> 3
A4: Bagian Kesejahteraan Rakyat Sekretariat Daerah | B4: =AVERAGE('Data Mentah'!B4:H4) -> 3 | C4: =AVERAGE('Data Mentah'!I4:O4) -> 2.5714286 | D4: =AVERAGE('Data Mentah'!P4:V4) -> 3 | E4: =AVERAGE('Data Mentah'!W4:AB4) -> 2.6666667 | F4: =AVERAGE('Data Mentah'!AC4:AJ4) -> 3
A5: Dinas Kesehatan | B5: =AVERAGE('Data Mentah'!B5:H5) -> 2.2857143 | C5: =AVERAGE('Data Mentah'!I5:O5) -> 2 | D5: =AVERAGE('Data Mentah'!P5:V5) -> 2.7142857 | E5: =AVERAGE('Data Mentah'!W5:AB5) -> 2.3333333 | F5: =AVERAGE('Data Mentah'!AC5:AJ5) -> 2.625
A6: DISPERPUSIP | B6: =AVERAGE('Data Mentah'!B6:H6) -> 2.5714286 | C6: =AVERAGE('Data Mentah'!I6:O6) -> 2 | D6: =AVERAGE('Data Mentah'!P6:V6) -> 3.4285714 | E6: =AVERAGE('Data Mentah'!W6:AB6) -> 1.8333333 | F6: =AVERAGE('Data Mentah'!AC6:AJ6) -> 2.25
A7: Bagian Perekonomian dan Sumber Daya Alam | B7: =AVERAGE('Data Mentah'!B7:H7) -> 3.5714286 | C7: =AVERAGE('Data Mentah'!I7:O7) -> 2.8571429 | D7: =AVERAGE('Data Mentah'!P7:V7) -> 3.7142857 | E7: =AVERAGE('Data Mentah'!W7:AB7) -> 3.1666667 | F7: =AVERAGE('Data Mentah'!AC7:AJ7) -> 3.375
A8: Dinas Sosial | B8: =AVERAGE('Data Mentah'!B8:H8) -> 3.5714286 | C8: =AVERAGE('Data Mentah'!I8:O8) -> 3 | D8: =AVERAGE('Data Mentah'!P8:V8) -> 3.2857143 | E8: =AVERAGE('Data Mentah'!W8:AB8) -> 3.8333333 | F8: =AVERAGE('Data Mentah'!AC8:AJ8) -> 3.625
A9: Dinas Kesehatan | B9: =AVERAGE('Data Mentah'!B9:H9) -> 3.1428571 | C9: =AVERAGE('Data Mentah'!I9:O9) -> 3.4285714 | D9: =AVERAGE('Data Mentah'!P9:V9) -> 4 | E9: =AVERAGE('Data Mentah'!W9:AB9) -> 3.6666667 | F9: =AVERAGE('Data Mentah'!AC9:AJ9) -> 3.5
A10: BKPSDM Kota Batu | B10: =AVERAGE('Data Mentah'!B10:H10) -> 3.1428571 | C10: =AVERAGE('Data Mentah'!I10:O10) -> 3 | D10: =AVERAGE('Data Mentah'!P10:V10) -> 3 | E10: =AVERAGE('Data Mentah'!W10:AB10) -> 3.1666667 | F10: =AVERAGE('Data Mentah'!AC10:AJ10) -> 3.125
A11: Badan Penanggulangan Bencana Daerah Kota Batu | B11: =AVERAGE('Data Mentah'!B11:H11) -> 4 | C11: =AVERAGE('Data Mentah'!I11:O11) -> 4 | D11: =AVERAGE('Data Mentah'!P11:V11) -> 4 | E11: =AVERAGE('Data Mentah'!W11:AB11) -> 4 | F11: =AVERAGE('Data Mentah'!AC11:AJ11) -> 4
A12: Dinas Pertanian dan Ketahanan Pangan | B12: =AVERAGE('Data Mentah'!B12:H12) -> 2.4285714 | C12: =AVERAGE('Data Mentah'!I12:O12) -> 2.2857143 | D12: =AVERAGE('Data Mentah'!P12:V12) -> 3.1428571 | E12: =AVERAGE('Data Mentah'!W12:AB12) -> 2.5 | F12: =AVERAGE('Data Mentah'!AC12:AJ12) -> 2.875
A13: Dinas Tenaga Kerja | B13: =AVERAGE('Data Mentah'!B13:H13) -> 4 | C13: =AVERAGE('Data Mentah'!I13:O13) -> 3.4285714 | D13: =AVERAGE('Data Mentah'!P13:V13) -> 3.4285714 | E13: =AVERAGE('Data Mentah'!W13:AB13) -> 3.1666667 | F13: =AVERAGE('Data Mentah'!AC13:AJ13) -> 3.375
... A49: Dinas PUPR | B49: =AVERAGE('Data Mentah'!B49:H49) -> 2.2857143 | C49: =AVERAGE('Data Mentah'!I49:O49) -> 1.5714286 | D49: =AVERAGE('Data Mentah'!P49:V49) -> 2.7142857 | E49: =AVERAGE('Data Mentah'!W49:AB49) -> 2.5 | F49: =AVERAGE('Data Mentah'!AC49:AJ49) -> 2.375

Sheet Analisis Deskriptif
A1: Variabel | B1: Mean | C1: Min | D1: Max | E1: StdDev
A2: X1_Komunikasi | B2: =AVERAGE('Skor Variabel'!B2:B49) -> 3.1220238 | C2: =MIN('Skor Variabel'!B2:B49) -> 2.1428571 | D2: =MAX('Skor Variabel'!B2:B49) -> 4 | E2: =_xlfn.STDEV.S('Skor Variabel'!B2:B49) -> 0.4974879
A3: X2_SumberDaya | B3: =AVERAGE('Skor Variabel'!B3:B50) -> 3.1398176 | C3: =MIN('Skor Variabel'!B3:B50) -> 2.1428571 | D3: =MAX('Skor Variabel'!B3:B50) -> 4 | E3: =_xlfn.STDEV.S('Skor Variabel'!B3:B50) -> 0.48718207
A4: X3_Disposisi | B4: =AVERAGE('Skor Variabel'!B4:B51) -> 3.1428571 | C4: =MIN('Skor Variabel'!B4:B51) -> 2.1428571 | D4: =MAX('Skor Variabel'!B4:B51) -> 4 | E4: =_xlfn.STDEV.S('Skor Variabel'!B4:B51) -> 0.49211469
A5: X4_StrukturBirokrasi | B5: =AVERAGE('Skor Variabel'!B5:B52) -> 3.1460317 | C5: =MIN('Skor Variabel'!B5:B52) -> 2.1428571 | D5: =MAX('Skor Variabel'!B5:B52) -> 4 | E5: =_xlfn.STDEV.S('Skor Variabel'!B5:B52) -> 0.49719892
A6: Y_Keberhasilan | B6: =AVERAGE('Skor Variabel'!B6:B53) -> 3.1655844 | C6: =MIN('Skor Variabel'!B6:B53) -> 2.1428571 | D6: =MAX('Skor Variabel'!B6:B53) -> 4 | E6: =_xlfn.STDEV.S('Skor Variabel'!B6:B53) -> 0.48513076

Sheet Siap Regresi
A1: X1_Komunikasi | B1: X2_SumberDaya | C1: X3_Disposisi | D1: X4_StrukturBirokrasi | E1: Y_Keberhasilan
A2: ='Skor Variabel'!B2 -> 2.2857143 | B2: ='Skor Variabel'!C2 -> 2.2857143 | C2: ='Skor Variabel'!D2 -> 2.7142857 | D2: ='Skor Variabel'!E2 -> 2.8333333 | E2: ='Skor Variabel'!F2 -> 2.375
A3: ='Skor Variabel'!B3 -> 3 | B3: ='Skor Variabel'!C3 -> 2.8571429 | C3: ='Skor Variabel'!D3 -> 3 | D3: ='Skor Variabel'!E3 -> 3.1666667 | E3: ='Skor Variabel'!F3 -> 3
A4: ='Skor Variabel'!B4 -> 3 | B4: ='Skor Variabel'!C4 -> 2.5714286 | C4: ='Skor Variabel'!D4 -> 3 | D4: ='Skor Variabel'!E4 -> 2.6666667 | E4: ='Skor Variabel'!F4 -> 3 | J4: SUMMARY OUTPUT
A5: ='Skor Variabel'!B5 -> 2.2857143 | B5: ='Skor Variabel'!C5 -> 2 | C5: ='Skor Variabel'!D5 -> 2.7142857 | D5: ='Skor Variabel'!E5 -> 2.3333333 | E5: ='Skor Variabel'!F5 -> 2.625
A6: ='Skor Variabel'!B6 -> 2.5714286 | B6: ='Skor Variabel'!C6 -> 2 | C6: ='Skor Variabel'!D6 -> 3.4285714 | D6: ='Skor Variabel'!E6 -> 1.8333333 | E6: ='Skor Variabel'!F6 -> 2.25 | J6: Regression Statistics
A7: ='Skor Variabel'!B7 -> 3.5714286 | B7: ='Skor Variabel'!C7 -> 2.8571429 | C7: ='Skor Variabel'!D7 -> 3.7142857 | D7: ='Skor Variabel'!E7 -> 3.1666667 | E7: ='Skor Variabel'!F7 -> 3.375 | J7: Multiple R | K7: 0.93301064
A8: ='Skor Variabel'!B8 -> 3.5714286 | B8: ='Skor Variabel'!C8 -> 3 | C8: ='Skor Variabel'!D8 -> 3.2857143 | D8: ='Skor Variabel'!E8 -> 3.8333333 | E8: ='Skor Variabel'!F8 -> 3.625 | J8: R Square | K8: 0.87050886
A9: ='Skor Variabel'!B9 -> 3.1428571 | B9: ='Skor Variabel'!C9 -> 3.4285714 | C9: ='Skor Variabel'!D9 -> 4 | D9: ='Skor Variabel'!E9 -> 3.6666667 | E9: ='Skor Variabel'!F9 -> 3.5 | J9: Adjusted R Square | K9: 0.85846317
A10: ='Skor Variabel'!B10 -> 3.1428571 | B10: ='Skor Variabel'!C10 -> 3 | C10: ='Skor Variabel'!D10 -> 3 | D10: ='Skor Variabel'!E10 -> 3.1666667 | E10: ='Skor Variabel'!F10 -> 3.125 | J10: Standard Error | K10: 0.15152924
A11: ='Skor Variabel'!B11 -> 4 | B11: ='Skor Variabel'!C11 -> 4 | C11: ='Skor Variabel'!D11 -> 4 | D11: ='Skor Variabel'!E11 -> 4 | E11: ='Skor Variabel'!F11 -> 4 | J11: Observations | K11: 48
A12: ='Skor Variabel'!B12 -> 2.4285714 | B12: ='Skor Variabel'!C12 -> 2.2857143 | C12: ='Skor Variabel'!D12 -> 3.1428571 | D12: ='Skor Variabel'!E12 -> 2.5 | E12: ='Skor Variabel'!F12 -> 2.875
A13: ='Skor Variabel'!B13 -> 4 | B13: ='Skor Variabel'!C13 -> 3.4285714 | C13: ='Skor Variabel'!D13 -> 3.4285714 | D13: ='Skor Variabel'!E13 -> 3.1666667 | E13: ='Skor Variabel'!F13 -> 3.375 | J13: ANOVA
A14: ='Skor Variabel'!B14 -> 4 | B14: ='Skor Variabel'!C14 -> 4 | C14: ='Skor Variabel'!D14 -> 4 | D14: ='Skor Variabel'!E14 -> 4 | E14: ='Skor Variabel'!F14 -> 4 | K14: df | L14: SS | M14: MS | N14: F | O14: Significance F
A15: ='Skor Variabel'!B15 -> 3 | B15: ='Skor Variabel'!C15 -> 2.5714286 | C15: ='Skor Variabel'!D15 -> 3 | D15: ='Skor Variabel'!E15 -> 3 | E15: ='Skor Variabel'!F15 -> 3 | J15: Regression | K15: 4 | L15: 6.6373467 | M15: 1.6593367 | N15: 72.267262 | O15: 1.6142795e-18
A16: ='Skor Variabel'!B16 -> 3.2857143 | B16: ='Skor Variabel'!C16 -> 3.4285714 | C16: ='Skor Variabel'!D16 -> 3.2857143 | D16: ='Skor Variabel'!E16 -> 3.6666667 | E16: ='Skor Variabel'!F16 -> 3.125 | J16: Residual | K16: 43 | L16: 0.9873278 | M16: 0.022961112
A17: ='Skor Variabel'!B17 -> 2.5714286 | B17: ='Skor Variabel'!C17 -> 2.2857143 | C17: ='Skor Variabel'!D17 -> 3.4285714 | D17: ='Skor Variabel'!E17 -> 2 | E17: ='Skor Variabel'!F17 -> 3 | J17: Total | K17: 47 | L17: 7.6246745
A18: ='Skor Variabel'!B18 -> 3 | B18: ='Skor Variabel'!C18 -> 2.7142857 | C18: ='Skor Variabel'!D18 -> 3.1428571 | D18: ='Skor Variabel'!E18 -> 2.8333333 | E18: ='Skor Variabel'!F18 -> 2.875
A19: ='Skor Variabel'!B19 -> 2.7142857 | B19: ='Skor Variabel'!C19 -> 2.8571429 | C19: ='Skor Variabel'!D19 -> 2.8571429 | D19: ='Skor Variabel'!E19 -> 2.8333333 | E19: ='Skor Variabel'!F19 -> 3 | K19: Coefficients | L19: Standard Error | M19: t Stat | N19: P-value | O19: Lower 95% | P19: Upper 95% | Q19: Lower 95,0% | R19: Upper 95,0%
A20: ='Skor Variabel'!B20 -> 4 | B20: ='Skor Variabel'!C20 -> 4 | C20: ='Skor Variabel'!D20 -> 4 | D20: ='Skor Variabel'!E20 -> 4 | E20: ='Skor Variabel'!F20 -> 4 | J20: Intercept | K20: 0.23996191 | L20: 0.19720812 | M20: 1.2167953 | N20: 0.23031873 | O20: -0.15774616 | P20: 0.63766999 | Q20: -0.15774616 | R20: 0.63766999
A21: ='Skor Variabel'!B21 -> 4 | B21: ='Skor Variabel'!C21 -> 4 | C21: ='Skor Variabel'!D21 -> 4 | D21: ='Skor Variabel'!E21 -> 4 | E21: ='Skor Variabel'!F21 -> 4 | J21: X1_Komunikasi | K21: 0.10923371 | L21: 0.07824761 | M21: 1.3960005 | N21: 0.16988061 | O21: -0.048567639 | P21: 0.26703505 | Q21: -0.048567639 | R21: 0.26703505
A22: ='Skor Variabel'!B22 -> 4 | B22: ='Skor Variabel'!C22 -> 4 | C22: ='Skor Variabel'!D22 -> 4 | D22: ='Skor Variabel'!E22 -> 4 | E22: ='Skor Variabel'!F22 -> 3.625 | J22: X2_SumberDaya | K22: 0.13158391 | L22: 0.095403315 | M22: 1.3792383 | N22: 0.17495304 | O22: -0.060815212 | P22: 0.32398303 | Q22: -0.060815212 | R22: 0.32398303
A23: ='Skor Variabel'!B23 -> 3 | B23: ='Skor Variabel'!C23 -> 3 | C23: ='Skor Variabel'!D23 -> 3 | D23: ='Skor Variabel'!E23 -> 3 | E23: ='Skor Variabel'!F23 -> 3 | J23: X3_Disposisi | K23: 0.36883893 | L23: 0.083231002 | M23: 4.431509 | N23: 6.3527249e-05 | O23: 0.20098762 | P23: 0.53669024 | Q23: 0.20098762 | R23: 0.53669024
A24: ='Skor Variabel'!B24 -> 3.2857143 | B24: ='Skor Variabel'!C24 -> 3 | C24: ='Skor Variabel'!D24 -> 3 | D24: ='Skor Variabel'!E24 -> 3 | E24: ='Skor Variabel'!F24 -> 3 | J24: X4_StrukturBirokrasi | K24: 0.31305548 | L24: 0.1032043 | M24: 3.0333569 | N24: 0.0040905909 | O24: 0.10492417 | P24: 0.52118679 | Q24: 0.10492417 | R24: 0.52118679
A25: ='Skor Variabel'!B25 -> 3.4285714 | B25: ='Skor Variabel'!C25 -> 2.8571429 | C25: ='Skor Variabel'!D25 -> 3.4285714 | D25: ='Skor Variabel'!E25 -> 3.1666667 | E25: ='Skor Variabel'!F25 -> 3.25
A26: ='Skor Variabel'!B26 -> 2.1428571 | B26: ='Skor Variabel'!C26 -> 2.5714286 | C26: ='Skor Variabel'!D26 -> 3 | D26: ='Skor Variabel'!E26 -> 3 | E26: ='Skor Variabel'!F26 -> 3
A27: ='Skor Variabel'!B27 -> 3 | B27: ='Skor Variabel'!C27 -> 2.4285714 | C27: ='Skor Variabel'!D27 -> 3.4285714 | D27: ='Skor Variabel'!E27 -> 2.8333333 | E27: ='Skor Variabel'!F27 -> 3 | J27: Variabel | K27: Koefisien | L27: P-Value | M27: Signifikan?
A28: ='Skor Variabel'!B28 -> 3 | B28: ='Skor Variabel'!C28 -> 3 | C28: ='Skor Variabel'!D28 -> 3 | D28: ='Skor Variabel'!E28 -> 3 | E28: ='Skor Variabel'!F28 -> 3 | J28: X1_Komunikasi | K28: 0.10923371 | L28: 0.16988061 | M28: Tidak
A29: ='Skor Variabel'!B29 -> 3 | B29: ='Skor Variabel'!C29 -> 3 | C29: ='Skor Variabel'!D29 -> 3 | D29: ='Skor Variabel'!E29 -> 3 | E29: ='Skor Variabel'!F29 -> 3.25 | J29: X2_SumberDaya | K29: 0.13158391 | L29: 0.17495304 | M29: Tidak
A30: ='Skor Variabel'!B30 -> 2.8571429 | B30: ='Skor Variabel'!C30 -> 2.5714286 | C30: ='Skor Variabel'!D30 -> 3.4285714 | D30: ='Skor Variabel'!E30 -> 3 | E30: ='Skor Variabel'!F30 -> 3.25 | J30: X3_Disposisi | K30: 0.36883893 | L30: 6.3527249e-05 | M30: Ya
A31: ='Skor Variabel'!B31 -> 2.8571429 | B31: ='Skor Variabel'!C31 -> 3 | C31: ='Skor Variabel'!D31 -> 3 | D31: ='Skor Variabel'!E31 -> 3.1666667 | E31: ='Skor Variabel'!F31 -> 3.125 | J31: X4_StrukturBirokrasi | K31: 0.31305548 | L31: 0.0040905909 | M31: Ya
A32: ='Skor Variabel'!B32 -> 3 | B32: ='Skor Variabel'!C32 -> 3 | C32: ='Skor Variabel'!D32 -> 3 | D32: ='Skor Variabel'!E32 -> 3 | E32: ='Skor Variabel'!F32 -> 3
A33: ='Skor Variabel'!B33 -> 2.7142857 | B33: ='Skor Variabel'!C33 -> 2.7142857 | C33: ='Skor Variabel'!D33 -> 3.5714286 | D33: ='Skor Variabel'!E33 -> 2.8333333 | E33: ='Skor Variabel'!F33 -> 3.125
A34: ='Skor Variabel'!B34 -> 3 | B34: ='Skor Variabel'!C34 -> 3 | C34: ='Skor Variabel'!D34 -> 3 | D34: ='Skor Variabel'!E34 -> 3 | E34: ='Skor Variabel'!F34 -> 3
A35: ='Skor Variabel'!B35 -> 3.7142857 | B35: ='Skor Variabel'!C35 -> 4 | C35: ='Skor Variabel'!D35 -> 4 | D35: ='Skor Variabel'!E35 -> 4 | E35: ='Skor Variabel'!F35 -> 4
A36: ='Skor Variabel'!B36 -> 3.4285714 | B36: ='Skor Variabel'!C36 -> 2.8571429 | C36: ='Skor Variabel'!D36 -> 3 | D36: ='Skor Variabel'!E36 -> 3 | E36: ='Skor Variabel'!F36 -> 3
A37: ='Skor Variabel'!B37 -> 3 | B37: ='Skor Variabel'!C37 -> 2.8571429 | C37: ='Skor Variabel'!D37 -> 3 | D37: ='Skor Variabel'!E37 -> 3 | E37: ='Skor Variabel'!F37 -> 3
A38: ='Skor Variabel'!B38 -> 3.2857143 | B38: ='Skor Variabel'!C38 -> 3 | C38: ='Skor Variabel'!D38 -> 3.1428571 | D38: ='Skor Variabel'!E38 -> 3 | E38: ='Skor Variabel'!F38 -> 3.125
A39: ='Skor Variabel'!B39 -> 3.4285714 | B39: ='Skor Variabel'!C39 -> 3.2857143 | C39: ='Skor Variabel'!D39 -> 3.7142857 | D39: ='Skor Variabel'!E39 -> 3.3333333 | E39: ='Skor Variabel'!F39 -> 3.625
A40: ='Skor Variabel'!B40 -> 3.2857143 | B40: ='Skor Variabel'!C40 -> 2.8571429 | C40: ='Skor Variabel'!D40 -> 3.2857143 | D40: ='Skor Variabel'!E40 -> 3 | E40: ='Skor Variabel'!F40 -> 3
...
